<?xml version="1.0" ?>
<robot name="AerialManipulator">

  <!-- To create a coordinate system for gripper -->
 <link name="endeffector">
 <inertial>
      <!-- <mass value="0.2"/> -->
  </inertial>
 </link>

  <link name="gripper">
    <inertial>
      <!-- <mass value="0.2"/> -->
    </inertial>
    <visual>
      <origin xyz="0 0 -.0207" rpy="0 0 0" />
      <geometry>
        <box size=".04 .022 .01" />
      </geometry>
      <material name="carbon">
        <color rgba="0.2 0.2 0.2 1.0"/>
      </material>
    </visual>
    <!-- Servo -->
    <visual>
      <origin xyz="0 0 -0.0357" rpy="0 0 0" />
      <geometry>
        <box size=".03 .015 .02" />
      </geometry>
      <material name="tmotor">
        <color rgba="0.4 0.4 0.4 1.0"/>
      </material>
    </visual>
    <!-- Finger -->
    <visual>
      <origin xyz=".018 0 -.0007" rpy="0 0 0" />
      <geometry>
        <box size=".004 .022 .03" />
      </geometry>
      <material name="tip">
        <color rgba="0.7 0.3 0.3 1.0"/>
      </material>
    </visual>
    <!-- Finger -->
    <visual>
      <origin xyz="-.018 0 -.0007" rpy="0 0 0" />
      <geometry>
        <box size=".004 .022 .03" />
      </geometry>
      <material name="tip">
        <color rgba="0.7 0.3 0.3 1.0"/>
      </material>
    </visual>
  </link>

  <link name="arm">
    <!-- Wrist Motor -->
    <visual>
      <origin xyz="0 0 -0.115" rpy="0 0 0" />
      <geometry>
        <cylinder radius=".0142" length="0.022"/>
      </geometry>
      <material name="motor" />
    </visual>
    <!-- Carbon Fiber Tube -->
    <visual>
      <origin xyz="0 0 -0.0407" rpy="0 0 0" />
      <geometry>
        <cylinder radius=".0075" length="0.115"/>
      </geometry>
      <material name="carbon">
        <color rgba="0.2 0.2 0.2 1.0"/>
      </material>
    </visual>
  </link>

  <link name="virtualvehicle">
    <!-- <inertial>
      <mass value="0.0000000000001"/>
      <inertia ixx="0.0000000000001" ixy="0.0" ixz="0.0" iyy="0.0000000000001" iyz="0.0" izz="0.0000000000001"/>
    </inertial> -->

    <!-- Spine -->
    <visual>
      <origin xyz="0 0 0" rpy="1.57079632679 0 0" />
      <geometry>
        <cylinder radius=".009" length=".036"/>
      </geometry>
      <material name="tmotor">
        <color rgba="0.4 0.4 0.4 1.0"/>
      </material>
    </visual>
    <!-- Printed Mounts -->
    <visual>
      <origin xyz="0 .0205 0" rpy="0 0 0" />
      <geometry>
        <box size=".048 .005 .02" />
      </geometry>
      <material name="print">
        <color rgba="0.9 0.9 0.9 1.0"/>
      </material>
    </visual>
    <visual>
      <origin xyz="0 -.0205 0" rpy="0 0 0" />
      <geometry>
        <box size=".048 .005 .02" />
      </geometry>
      <material name="print">
        <color rgba="0.9 0.9 0.9 1.0"/>
      </material>
    </visual>
    <!-- Plates -->
    <visual>
      <origin xyz="0 .061 -.0115" rpy="0 0 0" />
      <geometry>
        <box size=".048 .086 .003" />
      </geometry>
      <material name="carbon">
        <color rgba="0.2 0.2 0.2 1.0"/>
      </material>
    </visual>
    <visual>
      <origin xyz="0 -.061 -.0115" rpy="0 0 0" />
      <geometry>
        <box size=".048 .086 .003" />
      </geometry>
      <material name="carbon">
        <color rgba="0.2 0.2 0.2 1.0"/>
      </material>
    </visual>
    <visual>
      <origin xyz="0 .061 -.0345" rpy="0 0 0" />
      <geometry>
        <box size=".048 .086 .003" />
      </geometry>
      <material name="carbon">
        <color rgba="0.2 0.2 0.2 1.0"/>
      </material>
    </visual>
    <visual>
      <origin xyz="0 -.061 -.0345" rpy="0 0 0" />
      <geometry>
        <box size=".048 .086 .003" />
      </geometry>
      <material name="carbon">
        <color rgba="0.2 0.2 0.2 1.0"/>
      </material>
    </visual>
    <!-- Standoffs -->
    <visual>
      <origin xyz=".02 .022 -.023" rpy="0 0 0" />
      <geometry>
        <cylinder radius=".002" length=".020"/>
      </geometry>
      <material name="tmotor">
        <color rgba="0.4 0.4 0.4 1.0"/>
      </material>
    </visual>
    <visual>
      <origin xyz=".02 -.022 -.023" rpy="0 0 0" />
      <geometry>
        <cylinder radius=".002" length=".020"/>
      </geometry>
      <material name="tmotor">
        <color rgba="0.4 0.4 0.4 1.0"/>
      </material>
    </visual>
    <visual>
      <origin xyz="-.02 .022 -.023" rpy="0 0 0" />
      <geometry>
        <cylinder radius=".002" length=".020"/>
      </geometry>
      <material name="tmotor">
        <color rgba="0.4 0.4 0.4 1.0"/>
      </material>
    </visual>
    <visual>
      <origin xyz="-.02 -.022 -.023" rpy="0 0 0" />
      <geometry>
        <cylinder radius=".002" length=".020"/>
      </geometry>
      <material name="tmotor">
        <color rgba="0.4 0.4 0.4 1.0"/>
      </material>
    </visual>
    <visual>
      <origin xyz=".02 .099 -.023" rpy="0 0 0" />
      <geometry>
        <cylinder radius=".002" length=".020"/>
      </geometry>
      <material name="tmotor">
        <color rgba="0.4 0.4 0.4 1.0"/>
      </material>
    </visual>
    <visual>
      <origin xyz=".02 -.099 -.023" rpy="0 0 0" />
      <geometry>
        <cylinder radius=".002" length=".020"/>
      </geometry>
      <material name="tmotor">
        <color rgba="0.4 0.4 0.4 1.0"/>
      </material>
    </visual>
    <visual>
      <origin xyz="-.02 .099 -.023" rpy="0 0 0" />
      <geometry>
        <cylinder radius=".002" length=".020"/>
      </geometry>
      <material name="tmotor">
        <color rgba="0.4 0.4 0.4 1.0"/>
      </material>
    </visual>
    <visual>
      <origin xyz="-.02 -.099 -.023" rpy="0 0 0" />
      <geometry>
        <cylinder radius=".002" length=".020"/>
      </geometry>
      <material name="tmotor">
        <color rgba="0.4 0.4 0.4 1.0"/>
      </material>
    </visual>
    <!-- Saddle -->
    <visual>
      <origin xyz="0 0 -.031" rpy="0 0 0" />
      <geometry>
        <box size=".009 .0455 .004" />
      </geometry>
      <material name="carbon">
        <color rgba="0.2 0.2 0.2 1.0"/>
      </material>
    </visual>
    <!-- Shoulder Motor -->
    <visual>
      <origin xyz="0 0 0" rpy="1.57079632679 0 0" />
      <geometry>
        <cylinder radius=".0278" length=".015"/>
      </geometry>
      <material name="tmotor">
        <color rgba="0.4 0.4 0.4 1.0"/>
      </material>
    </visual>
    <!-- Arms -->
    <visual>
      <origin xyz=".057025 .062426 -0.008" rpy="0 0 0.575959" />
      <geometry>
        <box size=".100 .014 .004" />
      </geometry>
      <material name="carbon">
        <color rgba="0.2 0.2 0.2 1.0"/>
      </material>
    </visual>
    <visual>
      <origin xyz=".057025 -.062426 -0.008" rpy="0 0 -0.575959" />
      <geometry>
        <box size=".100 .014 .004" />
      </geometry>
      <material name="carbon">
        <color rgba="0.2 0.2 0.2 1.0"/>
      </material>
    </visual>
    <visual>
      <origin xyz="-.057025 .062426 -0.008" rpy="0 0 -0.575959" />
      <geometry>
        <box size=".100 .014 .004" />
      </geometry>
      <material name="carbon">
        <color rgba="0.2 0.2 0.2 1.0"/>
      </material>
    </visual>
    <visual>
      <origin xyz="-.057025 -.062426 -0.008" rpy="0 0 0.575959" />
      <geometry>
        <box size=".100 .014 .004" />
      </geometry>
      <material name="carbon">
        <color rgba="0.2 0.2 0.2 1.0"/>
      </material>
    </visual>
    <!-- Battery -->
    <visual>
      <origin xyz="0 .060 0" rpy="0 0 0" />
      <geometry>
        <box size=".036 .071 .022" />
      </geometry>
      <material name="battery">
        <color rgba="0.2 0.5 0.5 1.0"/>
      </material>
    </visual>
    <visual>
      <origin xyz="0 -.060 0" rpy="0 0 0" />
      <geometry>
        <box size=".036 .071 .022" />
      </geometry>
      <material name="battery">
        <color rgba="0.2 0.5 0.5 1.0"/>
      </material>
    </visual>

  </link>

  <link name="COM">
    <visual>
      <geometry>
        <sphere radius="0.015"/>
      </geometry>
      <material name="blue">
            <color rgba="0.2 0.2 0.2 1.0"/>
      </material>
    </visual>
  </link>
  <link name="vehicle">
  <inertial>
      <mass value="0.8"/> <!-- 0.706028   83527633 -->
      <inertia ixx="0.003063" ixy="0.000004" ixz="0.000000" iyy="0.001720" iyz="0.000028" izz="0.004585"/>
      <origin rpy="0 0 0" xyz="0.0 0.04 0.0"/>
    </inertial>
  </link>

  <!-- Physical Joints -->
  

  <joint name="gripper_attachment" type="fixed" dont_collapse="true">
    <parent link="endeffector"/>
    <child link="gripper"/>
    <origin rpy="-1.57079632679 0 0" xyz="0 0 0"/>
  </joint>

  <joint name="arm_attachment" type="fixed" dont_collapse="true">
    <parent link="gripper"/>
    <child link="arm"/>
    <origin rpy="0 0 0" xyz="0 0 -0.05"/>
  </joint>

  <joint name="vehicle_attachment" type="fixed" dont_collapse="true">
    <parent link="arm"/>
    <child link="virtualvehicle"/>
    <origin rpy="1.57079632679 1.57079632679 0" xyz="0 0 -0.15"/>
  </joint>

  <joint name="vehicle_yaw_fix" type="fixed" dont_collapse="true">
    <parent link="virtualvehicle"/>
    <child link="vehicle"/>
    <origin rpy="0 0 1.57079632679" xyz="0 0 0"/>
  </joint>

  <joint name="com_placement" type="fixed" dont_collapse="true">
    <parent link="endeffector"/>
    <child link="COM"/>
    <origin rpy="0 0 0" xyz="0 -0.16 0"/>
  </joint>







  <!-- Materials -->

  <material name="wash">
    <color rgba="1 0 0 .15"/>
  </material>
  <material name="prop">
    <color rgba="1 0 0 1"/>
  </material>

  <!-- Motors -->
  <material name="motor">
    <color rgba="0.5 0.5 .5 1.0"/>
  </material>

  <link name="motor1">
    <visual>
      <origin xyz="0 0 0" rpy="0 0 0" />
      <geometry>
        <cylinder radius=".0142" length="0.022"/>
      </geometry>
      <material name="motor" />
    </visual>
  </link>
  <link name="motor2">
    <visual>
      <origin xyz="0 0 0" rpy="0 0 0" />
      <geometry>
        <cylinder radius=".0142" length="0.022"/>
      </geometry>
      <material name="motor" />
    </visual>
  </link>
  <link name="motor3">
    <visual>
      <origin xyz="0 0 0" rpy="0 0 0" />
      <geometry>
        <cylinder radius=".0142" length="0.022"/>
      </geometry>
      <material name="motor" />
    </visual>
  </link>
  <link name="motor4">
    <visual>
      <origin xyz="0 0 0" rpy="0 0 0" />
      <geometry>
        <cylinder radius=".0142" length="0.022"/>
      </geometry>
      <material name="motor" />
    </visual>
  </link>

  <link name="prop1">
    <visual>
      <origin xyz="0 0 0" rpy="0 0 0" />
      <geometry>
        <cylinder radius=".06477" length="0.007"/>
      </geometry>
      <material name="wash" />
    </visual>
  </link>
  <link name="prop2">
    <visual>
      <origin xyz="0 0 0" rpy="0 0 0" />
      <geometry>
        <cylinder radius=".06477" length="0.007"/>
      </geometry>
      <material name="wash" />
    </visual>
  </link>
  <link name="prop3">
    <visual>
      <origin xyz="0 0 0" rpy="0 0 0" />
      <geometry>
        <cylinder radius=".06477" length="0.007"/>
      </geometry>
      <material name="wash" />
    </visual>
  </link>
  <link name="prop4">
    <visual>
      <origin xyz="0 0 0" rpy="0 0 0" />
      <geometry>
        <cylinder radius=".06477" length="0.007"/>
      </geometry>
      <material name="wash" />
    </visual>
  </link>




  <joint name="motor1" type="fixed" dont_collapse="true">
    <parent link="virtualvehicle"/>
    <child link="motor1"/>
    <origin xyz=".09057 .084212 .004" rpy="0 0 0" />
  </joint>
  <joint name="motor2" type="fixed" dont_collapse="true">
    <parent link="virtualvehicle"/>
    <child link="motor2"/>
    <origin xyz="-.09057 .084212 .004" rpy="0 0 0" />
  </joint>
  <joint name="motor3" type="fixed" dont_collapse="true">
    <parent link="virtualvehicle"/>
    <child link="motor3"/>
    <origin xyz="-.09057 -.084212 .004" rpy="0 0 0" />
  </joint>
  <joint name="motor4" type="fixed" dont_collapse="true">
    <parent link="virtualvehicle"/>
    <child link="motor4"/>
    <origin xyz=".09057 -.084212 .004" rpy="0 0 0" />
  </joint>

  <joint name="prop1" type="continuous">
    <parent link="motor1"/>
    <child link="prop1"/>
    <origin xyz="0 0 0.01" rpy="0 0 0"/>
    <axis rpy="0 0 0" xyz="0 0 1"/>
  </joint>
  <joint name="prop2" type="continuous">
    <parent link="motor2"/>
    <child link="prop2"/>
    <origin xyz="0 0 0.01" rpy="0 0 0"/>
    <axis rpy="0 0 0" xyz="0 0 1"/>
  </joint>
  <joint name="prop3" type="continuous">
    <parent link="motor3"/>
    <child link="prop3"/>
    <origin xyz="0 0 0.01" rpy="0 0 0"/>
    <axis rpy="0 0 0" xyz="0 0 1"/>
  </joint>
  <joint name="prop4" type="continuous">
    <parent link="motor4"/>
    <child link="prop4"/>
    <origin xyz="0 0 0.01" rpy="0 0 0"/>
    <axis rpy="0 0 0" xyz="0 0 1"/>
  </joint>



  <!--

   Uncomment below to view this URDF with rviz. (Needs a base link with no inertia)

   Run the following command to visualize and manipulate the joints:

   roslaunch urdf_tutorial display.launch model:=aerialmanipulator.urdf

   (must be in same directory as this file, called aerialmanipulator.urdf)

 -->

  <!-- <link name="base_link"></link>
  <joint name="world" type="fixed">
    <parent link="base_link"/>
    <child link="endeffector"/>
    <origin rpy="0 0 0" xyz=" 0 0 0"/>
  </joint> -->



</robot>